<sdf version='1.7'>
  <model name='ur5_4dof'>
    <link name='base_link'>
      <inertial>
        <pose>0 0 0 0 -0 0</pose>
        <mass>5</mass>
        <inertia>
          <ixx>0.1</ixx>
          <ixy>0</ixy>
          <ixz>0</ixz>
          <iyy>0.1</iyy>
          <iyz>0</iyz>
          <izz>0.1</izz>
        </inertia>
      </inertial>
      <collision name='base_link_collision'>
        <pose>0 0 0.003 0 -0 2.35619</pose>
        <geometry>
          <mesh>
            <scale>1 1 1</scale>
            <uri>model://ur_description/meshes/ur5/visual/base.dae</uri>
          </mesh>
        </geometry>
      </collision>
      <visual name='base_link_visual'>
        <pose>0 0 0.003 0 -0 2.35619</pose>
        <geometry>
          <mesh>
            <scale>1 1 1</scale>
            <uri>model://ur_description/meshes/ur5/visual/base.dae</uri>
          </mesh>
        </geometry>
      </visual>
    </link>
    <joint name='shoulder_pan_joint' type='revolute'>
      <pose relative_to='base_link'>0 0 0.089159 0 -0 0</pose>
      <parent>base_link</parent>
      <child>shoulder_link</child>
      <axis>
        <xyz>0 0 1</xyz>
        <limit>
          <lower>-6.28319</lower>
          <upper>6.28319</upper>
          <effort>150</effort>
          <velocity>3.14159</velocity>
        </limit>
        <dynamics>
          <spring_reference>0</spring_reference>
          <spring_stiffness>0</spring_stiffness>
        </dynamics>
      </axis>
    </joint>
    <link name='shoulder_link'>
      <pose relative_to='shoulder_pan_joint'>0 0 0 0 -0 0</pose>
      <inertial>
        <pose>0 0 0 0 -0 0</pose>
        <mass>4</mass>
        <inertia>
          <ixx>0.08</ixx>
          <ixy>0</ixy>
          <ixz>0</ixz>
          <iyy>0.08</iyy>
          <iyz>0</iyz>
          <izz>0.08</izz>
        </inertia>
      </inertial>
      <collision name='shoulder_link_collision'>
        <pose>0 0 0 0 -0 0</pose>
        <geometry>
          <mesh>
            <scale>1 1 1</scale>
            <uri>model://ur_description/meshes/ur5/visual/shoulder.dae</uri>
          </mesh>
        </geometry>
      </collision>
      <visual name='shoulder_link_visual'>
        <pose>0 0 0 0 -0 0</pose>
        <geometry>
          <mesh>
            <scale>1 1 1</scale>
            <uri>model://ur_description/meshes/ur5/visual/shoulder.dae</uri>
          </mesh>
        </geometry>
      </visual>
    </link>
    <joint name='shoulder_lift_joint' type='revolute'>
      <pose relative_to='shoulder_link'>0 0.13585 0 0 1.5708 0</pose>
      <parent>shoulder_link</parent>
      <child>upper_arm_link</child>
      <axis>
        <xyz>0 1 0</xyz>
        <limit>
          <lower>-6.28319</lower>
          <upper>6.28319</upper>
          <effort>150</effort>
          <velocity>3.14159</velocity>
        </limit>
        <dynamics>
          <spring_reference>0</spring_reference>
          <spring_stiffness>0</spring_stiffness>
        </dynamics>
      </axis>
    </joint>
    <link name='upper_arm_link'>
      <pose relative_to='shoulder_lift_joint'>0 0 0 0 -0 0</pose>
      <inertial>
        <pose>0 0 0 0 -0 0</pose>
        <mass>3</mass>
        <inertia>
          <ixx>0.06</ixx>
          <ixy>0</ixy>
          <ixz>0</ixz>
          <iyy>0.06</iyy>
          <iyz>0</iyz>
          <izz>0.06</izz>
        </inertia>
      </inertial>
      <collision name='upper_arm_link_collision'>
        <pose>0 0 0 0 -0 0</pose>
        <geometry>
          <mesh>
            <scale>1 1 1</scale>
            <uri>model://ur_description/meshes/ur5/visual/upperarm.dae</uri>
          </mesh>
        </geometry>
      </collision>
      <visual name='upper_arm_link_visual'>
        <pose>0 0 0 0 -0 0</pose>
        <geometry>
          <mesh>
            <scale>1 1 1</scale>
            <uri>model://ur_description/meshes/ur5/visual/upperarm.dae</uri>
          </mesh>
        </geometry>
      </visual>
    </link>
    <joint name='elbow_joint' type='revolute'>
      <pose relative_to='upper_arm_link'>0 -0.1197 0.425 0 -0 0</pose>
      <parent>upper_arm_link</parent>
      <child>forearm_link</child>
      <axis>
        <xyz>0 1 0</xyz>
        <limit>
          <lower>-6.28319</lower>
          <upper>6.28319</upper>
          <effort>150</effort>
          <velocity>3.14159</velocity>
        </limit>
        <dynamics>
          <spring_reference>0</spring_reference>
          <spring_stiffness>0</spring_stiffness>
        </dynamics>
      </axis>
    </joint>
    <link name='forearm_link'>
      <pose relative_to='elbow_joint'>0 0 0 0 -0 0</pose>
      <inertial>
        <pose>0 0 0 0 -0 0</pose>
        <mass>2.5</mass>
        <inertia>
          <ixx>0.05</ixx>
          <ixy>0</ixy>
          <ixz>0</ixz>
          <iyy>0.05</iyy>
          <iyz>0</iyz>
          <izz>0.05</izz>
        </inertia>
      </inertial>
      <collision name='forearm_link_collision'>
        <pose>0 0 0 0 -0 0</pose>
        <geometry>
          <mesh>
            <scale>1 1 1</scale>
            <uri>model://ur_description/meshes/ur5/visual/forearm.dae</uri>
          </mesh>
        </geometry>
      </collision>
      <visual name='forearm_link_visual'>
        <pose>0 0 0 0 -0 0</pose>
        <geometry>
          <mesh>
            <scale>1 1 1</scale>
            <uri>model://ur_description/meshes/ur5/visual/forearm.dae</uri>
          </mesh>
        </geometry>
      </visual>
    </link>
    <joint name='wrist_joint' type='revolute'>
      <pose relative_to='forearm_link'>0 0 0.39225 0 -0 0</pose>
      <parent>forearm_link</parent>
      <child>wrist_link</child>
      <axis>
        <xyz>0 1 0</xyz>
        <limit>
          <lower>-3.14159</lower>
          <upper>0.785398</upper>
          <effort>28</effort>
          <velocity>3.14159</velocity>
        </limit>
        <dynamics>
          <spring_reference>0</spring_reference>
          <spring_stiffness>0</spring_stiffness>
        </dynamics>
      </axis>
    </joint>
    <link name='wrist_link'>
      <pose relative_to='wrist_joint'>0 0 0 0 -0 0</pose>
      <inertial>
        <pose>0.002649 0.040847 0.080309 0 -0 0</pose>
        <mass>5.98287</mass>
        <inertia>
          <ixx>0.141893</ixx>
          <ixy>-0.00117215</ixy>
          <ixz>-0.00116721</ixz>
          <iyy>0.128114</iyy>
          <iyz>-0.00223116</iyz>
          <izz>0.110391</izz>
        </inertia>
      </inertial>
      <collision name='wrist_link_collision'>
        <pose>0 0 0 0 -0 0</pose>
        <geometry>
          <mesh>
            <scale>1 1 1</scale>
            <uri>model://ur_description/meshes/ur5/visual/wrist1.dae</uri>
          </mesh>
        </geometry>
      </collision>
      <collision name='wrist_link_fixed_joint_lump__ee_link_collision_1'>
        <pose>0 0 0.17695 0 -0 0</pose>
        <geometry>
          <box>
            <size>0.05 0.05 0.05</size>
          </box>
        </geometry>
      </collision>
      <collision name='wrist_link_fixed_joint_lump__grip_mount_link_collision_2'>
        <pose>0 0.0943 0.04295 0 -0 0</pose>
        <geometry>
          <box>
            <size>0.03 0.02 0.02</size>
          </box>
        </geometry>
      </collision>
      <collision name='wrist_link_fixed_joint_lump__gripper_camera_link_collision_3'>
        <pose>0.0317 0.1148 0.15395 -0 -0.26179 1.5693</pose>
        <geometry>
          <mesh>
            <scale>0.0025 0.0024 0.0012</scale>
            <uri>model://ur5_4dof/meshes/camera.dae</uri>
          </mesh>
        </geometry>
        <surface>
          <contact>
            <ode/>
          </contact>
          <friction>
            <ode/>
          </friction>
        </surface>
      </collision>
      <collision name='wrist_link_fixed_joint_lump__robotiq_hande_coupler_collision_4'>
        <pose>0 0.0943 0.0484 0 -0 0</pose>
        <geometry>
          <cylinder>
            <length>0.0169</length>
            <radius>0.0385</radius>
          </cylinder>
        </geometry>
      </collision>
      <collision name='wrist_link_fixed_joint_lump__robotiq_hande_link_collision_5'>
        <pose>0 0.0943 0.1074 0 -0 0</pose>
        <geometry>
          <cylinder>
            <length>0.1069</length>
            <radius>0.0385</radius>
          </cylinder>
        </geometry>
      </collision>
      <visual name='wrist_link_visual'>
        <pose>0 0 0 0 -0 0</pose>
        <geometry>
          <mesh>
            <scale>1 1 1</scale>
            <uri>model://ur_description/meshes/ur5/visual/wrist1.dae</uri>
          </mesh>
        </geometry>
      </visual>
      <visual name='wrist_link_fixed_joint_lump__gripper_camera_link_visual_1'>
        <pose>0.0317 0.1148 0.15395 -0 -0.26179 1.5693</pose>
        <geometry>
          <mesh>
            <scale>0.0025 0.0024 0.0012</scale>
            <uri>model://ur5_4dof/meshes/camera.dae</uri>
          </mesh>
        </geometry>
      </visual>
      <visual name='wrist_link_fixed_joint_lump__robotiq_hande_coupler_visual_2'>
        <pose>0 0.0943 0.04295 0 -0 0</pose>
        <geometry>
          <mesh>
            <scale>1 1 1</scale>
            <uri>model://robotiq_hande_description/meshes/io_coupler.dae</uri>
          </mesh>
        </geometry>
      </visual>
      <visual name='wrist_link_fixed_joint_lump__robotiq_hande_link_visual_3'>
        <pose>0 0.0943 0.05395 0 -0 0</pose>
        <geometry>
          <mesh>
            <scale>1 1 1</scale>
            <uri>model://robotiq_hande_description/meshes/hande.dae</uri>
          </mesh>
        </geometry>
      </visual>
      <sensor name='gazebo_camera' type='camera'>
        <always_on>1</always_on>
        <update_rate>30</update_rate>
        <camera>
          <horizontal_fov>1.047</horizontal_fov>
          <image>
            <width>640</width>
            <height>480</height>
            <format>R8G8B8</format>
          </image>
          <clip>
            <near>0.1</near>
            <far>100</far>
          </clip>
        </camera>
        <plugin name='gazebo_ros_camera' filename='libgazebo_ros_camera.so'>
          <ros>
            <namespace>/camera</namespace>
            <remapping>
              <remap from='/image_raw' to='/camera/image_raw'/>
            </remapping>
          </ros>
          <cameraName>gazebo_camera</cameraName>
          <imageTopicName>image_raw</imageTopicName>
          <cameraInfoTopicName>camera_info</cameraInfoTopicName>
          <frameName>gripper_camera_link</frameName>
        </plugin>
        <pose>0.0317 0.1148 0.15395 -0 -0.26179 1.5693</pose>
      </sensor>
    </link>
  </model>
</sdf>
